<?xml version="1.0" ?>
<sdf version="1.6">
  <model name="robocar_1_10">
    <static>false</static>
    
    <link name="base">
      <pose>0.0 0.0 0.0 0 0 0</pose>

      <inertial>
        <mass>3.0</mass>
        <pose>0.125 0.0 0.07 0 0 0</pose>
        <inertia>
          <ixx>0.03</ixx>
          <ixy>0.0</ixy>
          <iyy>0.050</iyy>
          <ixz>0.0</ixz>
          <iyz>0.0</iyz>
          <izz>0.054</izz>
        </inertia>
      </inertial>

      <collision name="collision">
        <pose>0.15 0.0 0.08</pose>
        <geometry>
          <box>
            <size>0.423 0.224 0.10</size>
          </box>
        </geometry>
      </collision>

      <visual name="visual">
        <geometry>
          <mesh>
            <uri>model://meshes/body.obj</uri>
          </mesh>
        </geometry>
      </visual>
    </link>

    <link name="rear_right_wheel">
      <pose>0.0 -0.07994 0.03165 0 0 0</pose>

      <inertial>
        <mass>0.2</mass>
        <inertia>
          <ixx>6.5e-5</ixx>
          <ixy>0.0</ixy>
          <iyy>1e-4</iyy>
          <ixz>0.0</ixz>
          <iyz>0.0</iyz>
          <izz>6.5e-5</izz>
        </inertia>
      </inertial>

      <visual name="visual">
        <pose>0.0 0.0 0.0 0 0 0.0</pose>
        <geometry>
          <mesh>
            <uri>model://meshes/tire.obj</uri>
          </mesh>
        </geometry>
      </visual>

      <collision name="collision">
        <pose>0.0 0.0 0.0 0 0 0</pose>
        <geometry>
          <!--cylinder>
            <radius>0.34</radius>
            <length>0.28826</length>
          </cylinder-->
          <sphere>
            <radius>0.03165</radius>
          </sphere>
        </geometry>
        <surface>
          <friction>
            <ode>
              <mu>1.1</mu>
              <mu2>1.1</mu2>
              <slip1>0.0</slip1>
              <slip2>0.0</slip2>
            </ode>
          </friction>
          <contact>
            <ode>
              <min_depth>0.001</min_depth>
              <kp>1e6</kp>
            </ode>
          </contact>
        </surface>
      </collision>

    </link>
    
    <link name="rear_right_wheel_holder">
      <pose relative_to="rear_right_wheel">0 0 0 0 0 0</pose>
    </link>
    
    <!--joint type="fixed" name="rear_right_wheel_choke_joint">
      <child>rear_right_wheel_holder</child>
      <parent>base</parent>
    </joint-->
    <joint type="prismatic" name="rear_right_wheel_choke_joint">
      <child>rear_right_wheel_holder</child>
      <parent>base</parent>
      <axis>
        <xyz>0 0 1</xyz>
        <limit>
          <lower>-0.03</lower>
          <upper>0.03</upper>
        </limit>
        <dynamics>
          <damping>1000</damping>
          <spring_stiffness>3000</spring_stiffness>
          <spring_reference>0</spring_reference>
        </dynamics>
      </axis>
      <physics>
        <ode>
          <implicit_spring_damper>1</implicit_spring_damper>
          <cfm_damping>1</cfm_damping>
        </ode>
      </physics>
    </joint>

    <link name="rear_left_wheel">
      <pose>0.0 0.07994 0.03165 0 0 0</pose>

      <inertial>
        <mass>0.2</mass>
        <inertia>
          <ixx>6.5e-5</ixx>
          <ixy>0.0</ixy>
          <iyy>1e-4</iyy>
          <ixz>0.0</ixz>
          <iyz>0.0</iyz>
          <izz>6.5e-5</izz>
        </inertia>
      </inertial>

      <visual name="visual">
        <pose>0.0 0.0 0.0 0 0 0.0</pose>
        <geometry>
          <mesh>
            <uri>model://meshes/tire.obj</uri>
          </mesh>
        </geometry>
      </visual>

      <collision name="collision">
        <pose>0.0 0.0 0.0 0 0 0</pose>
        <geometry>
          <!--cylinder>
            <radius>0.34</radius>
            <length>0.28826</length>
          </cylinder-->
          <sphere>
            <radius>0.03165</radius>
          </sphere>
        </geometry>
        <surface>
          <friction>
            <ode>
              <mu>1.1</mu>
              <mu2>1.1</mu2>
              <slip1>0.0</slip1>
              <slip2>0.0</slip2>
            </ode>
          </friction>
          <contact>
            <ode>
              <min_depth>0.001</min_depth>
              <kp>1e6</kp>
            </ode>
          </contact>
        </surface>
      </collision>

    </link>
    
    <link name="rear_left_wheel_holder">
      <pose relative_to="rear_left_wheel">0 0 0 0 0 0</pose>
    </link>
    
    <!--joint type="fixed" name="rear_left_wheel_choke_joint">
      <child>rear_left_wheel_holder</child>
      <parent>base</parent>
    </joint-->
    <joint type="prismatic" name="rear_left_wheel_choke_joint">
      <child>rear_left_wheel_holder</child>
      <parent>base</parent>
      <axis>
        <xyz>0 0 1</xyz>
        <limit>
          <lower>-0.03</lower>
          <upper>0.03</upper>
        </limit>
        <dynamics>
          <damping>1000</damping>
          <spring_stiffness>3000</spring_stiffness>
          <spring_reference>0</spring_reference>
        </dynamics>
      </axis>
      <physics>
        <ode>
          <implicit_spring_damper>1</implicit_spring_damper>
          <cfm_damping>1</cfm_damping>
        </ode>
      </physics>
    </joint>

    <link name="front_right_wheel">
      <pose>0.2568 -0.07994 0.03165 0 0 0</pose>

      <inertial>
        <mass>0.2</mass>
        <inertia>
          <ixx>6.5e-5</ixx>
          <ixy>0.0</ixy>
          <iyy>1e-4</iyy>
          <ixz>0.0</ixz>
          <iyz>0.0</iyz>
          <izz>6.5e-5</izz>
        </inertia>
      </inertial>

      <visual name="visual">
        <pose>0.0 0.0 0.0 0 0 0.0</pose>
        <geometry>
          <mesh>
            <uri>model://meshes/tire.obj</uri>
          </mesh>
        </geometry>
      </visual>

      <collision name="collision">
        <pose>0.0 0.0 0.0 0 0 0</pose>
        <geometry>
          <!--cylinder>
            <radius>0.34</radius>
            <length>0.28826</length>
          </cylinder-->
          <sphere>
            <radius>0.03165</radius>
          </sphere>
        </geometry>
        <surface>
          <friction>
            <ode>
              <mu>0.9</mu>
              <mu2>0.9</mu2>
              <slip1>0.0</slip1>
              <slip2>0.0</slip2>
            </ode>
          </friction>
          <contact>
            <ode>
              <min_depth>0.001</min_depth>
              <kp>1e6</kp>
            </ode>
          </contact>
        </surface>
      </collision>

    </link>
    
    <link name="front_right_wheel_suspension">
      <pose relative_to="front_right_wheel">0 0 0 0 0 0</pose>
    </link>

    <link name="front_right_wheel_holder">
      <pose relative_to="front_right_wheel">0 0 0 0 0 0</pose>
    </link>
    
    <!--joint type="fixed" name="front_right_wheel_choke_joint">
      <child>front_right_wheel_suspension</child>
      <parent>base</parent>
    </joint-->
    <joint type="prismatic" name="front_right_wheel_choke_joint">
      <child>front_right_wheel_suspension</child>
      <parent>base</parent>
      <axis>
        <xyz>0 0 1</xyz>
        <limit>
          <lower>-0.03</lower>
          <upper>0.03</upper>
        </limit>
        <dynamics>
          <damping>1000</damping>
          <spring_stiffness>3000</spring_stiffness>
          <spring_reference>0</spring_reference>
        </dynamics>
      </axis>
      <physics>
        <ode>
          <implicit_spring_damper>1</implicit_spring_damper>
          <cfm_damping>1</cfm_damping>
        </ode>
      </physics>
    </joint>

    <link name="front_left_wheel">
      <pose>0.2568 0.07994 0.03165 0 0 0</pose>

      <inertial>
        <mass>0.2</mass>
        <inertia>
          <ixx>6.5e-5</ixx>
          <ixy>0.0</ixy>
          <iyy>1e-4</iyy>
          <ixz>0.0</ixz>
          <iyz>0.0</iyz>
          <izz>6.5e-5</izz>
        </inertia>
      </inertial>

      <visual name="visual">
        <pose>0.0 0.0 0.0 0 0 0.0</pose>
        <geometry>
          <mesh>
            <uri>model://meshes/tire.obj</uri>
          </mesh>
        </geometry>
      </visual>

      <collision name="collision">
        <pose>0.0 0.0 0.0 0 0 0</pose>
        <geometry>
          <!--cylinder>
            <radius>0.34</radius>
            <length>0.28826</length>
          </cylinder-->
          <sphere>
            <radius>0.03165</radius>
          </sphere>
        </geometry>
        <surface>
          <friction>
            <ode>
              <mu>0.9</mu>
              <mu2>0.9</mu2>
              <slip1>0.0</slip1>
              <slip2>0.0</slip2>
            </ode>
          </friction>
          <contact>
            <ode>
              <min_depth>0.001</min_depth>
              <kp>1e6</kp>
            </ode>
          </contact>
        </surface>
      </collision>

    </link>
    
    <link name="front_left_wheel_suspension">
      <pose relative_to="front_left_wheel">0 0 0 0 0 0</pose>
    </link>

    <link name="front_left_wheel_holder">
      <pose relative_to="front_left_wheel">0 0 0 0 0 0</pose>
    </link>
    
    <!--joint type="fixed" name="front_left_wheel_choke_joint">
      <child>front_left_wheel_suspension</child>
      <parent>base</parent>
    </joint-->
    <joint type="prismatic" name="front_left_wheel_choke_joint">
      <child>front_left_wheel_suspension</child>
      <parent>base</parent>
      <axis>
        <xyz>0 0 1</xyz>
        <limit>
          <lower>-0.03</lower>
          <upper>0.03</upper>
        </limit>
        <dynamics>
          <damping>1000</damping>
          <spring_stiffness>3000</spring_stiffness>
          <spring_reference>0</spring_reference>
        </dynamics>
      </axis>
      <physics>
        <ode>
          <implicit_spring_damper>1</implicit_spring_damper>
          <cfm_damping>1</cfm_damping>
        </ode>
      </physics>
    </joint>

    <joint type="revolute" name="front_left_steer_joint">
      <child>front_left_wheel_holder</child>
      <parent>front_left_wheel_suspension</parent>
      <axis>
        <xyz>0 0 1</xyz>
        <limit>
          <lower>-0.5585</lower>
          <upper>0.5585</upper>
        </limit>
      </axis>
    </joint>

    <joint type="revolute" name="front_left_wheel_joint">
      <child>front_left_wheel</child>
      <parent>front_left_wheel_holder</parent>
      <axis>
        <xyz>0 1 0</xyz>
        <dynamics>
          <friction>0.2</friction>
        </dynamics>
      </axis>
    </joint>

    <joint type="revolute" name="front_right_steer_joint">
      <child>front_right_wheel_holder</child>
      <parent>front_right_wheel_suspension</parent>
      <axis>
        <xyz>0 0 1</xyz>
        <limit>
          <lower>-0.5585</lower>
          <upper>0.5585</upper>
        </limit>
      </axis>
    </joint>

    <joint type="revolute" name="front_right_wheel_joint">
      <child>front_right_wheel</child>
      <parent>front_right_wheel_holder</parent>
      <axis>
        <xyz>0 1 0</xyz>
        <dynamics>
          <friction>0.2</friction>
        </dynamics>
      </axis>
    </joint>

    <joint type="revolute" name="rear_left_wheel_joint">
      <pose>0 0 0 0 0 0</pose>
      <child>rear_left_wheel</child>
      <parent>rear_left_wheel_holder</parent>
      <axis>
        <xyz>0 1 0</xyz>
        <dynamics>
          <friction>0.2</friction>
        </dynamics>
      </axis>
    </joint>

    <joint type="revolute" name="rear_right_wheel_joint">
      <pose>0 0 0 0 0 0</pose>
      <child>rear_right_wheel</child>
      <parent>rear_right_wheel_holder</parent>
      <axis>
        <xyz>0 1 0</xyz>
        <dynamics>
          <friction>0.2</friction>
        </dynamics>
      </axis>
    </joint>

    <joint name="steering_joint" type="revolute">
      <pose>0 0 0 0 0 0</pose>
      <parent>base</parent>
      <child>steering_wheel</child>
      <axis>
        <xyz>-1 0 0.47</xyz>
        <limit>
          <lower>-7.85</lower>
          <upper>7.85</upper>
        </limit>
        <dynamics>
          <damping>1.0</damping>
        </dynamics>
        <use_parent_model_frame>true</use_parent_model_frame>
      </axis>
      <physics>
        <ode>
          <cfm_damping>1</cfm_damping>
        </ode>
      </physics>
    </joint>

    <link name="steering_wheel">
      <pose>0.15 0.0 0.2 0 0 0</pose>
      <inertial>
        <mass>0.1</mass>
        <inertia>
          <ixx>0.0014583300</ixx>
          <ixy>0</ixy>
          <ixz>0</ixz>
          <iyy>0.0014583300</iyy>
          <iyz>0</iyz>
          <izz>0.0012500000</izz>
        </inertia>
      </inertial>
    </link>
  </model>
</sdf>
